<?xml version="1.0" ?>
<!-- =================================================================================== -->
<!-- |    This document was autogenerated by xacro from urdf/1122_v3.xacro             | -->
<!-- |    EDITING THIS FILE BY HAND IS NOT RECOMMENDED                                 | -->
<!-- =================================================================================== -->
<robot xmlns:xacro="http://www.ros.org/wiki/xacro" name="1122_v3">
  <material name="silver">
    <color rgba="0.700 0.700 0.700 1.000"/>
  </material>
  <transmission name="Revolute 1_tran">
    <type>transmission_interface/SimpleTransmission</type>
    <joint name="Revolute 1">
      <hardwareInterface>hardware_interface/EffortJointInterface</hardwareInterface>
    </joint>
    <actuator name="Revolute 1_actr">
      <hardwareInterface>hardware_interface/EffortJointInterface</hardwareInterface>
      <mechanicalReduction>1</mechanicalReduction>
    </actuator>
  </transmission>
  <transmission name="Revolute 2_tran">
    <type>transmission_interface/SimpleTransmission</type>
    <joint name="Revolute 2">
      <hardwareInterface>hardware_interface/EffortJointInterface</hardwareInterface>
    </joint>
    <actuator name="Revolute 2_actr">
      <hardwareInterface>hardware_interface/EffortJointInterface</hardwareInterface>
      <mechanicalReduction>1</mechanicalReduction>
    </actuator>
  </transmission>
  <transmission name="Revolute 3_tran">
    <type>transmission_interface/SimpleTransmission</type>
    <joint name="Revolute 3">
      <hardwareInterface>hardware_interface/EffortJointInterface</hardwareInterface>
    </joint>
    <actuator name="Revolute 3_actr">
      <hardwareInterface>hardware_interface/EffortJointInterface</hardwareInterface>
      <mechanicalReduction>1</mechanicalReduction>
    </actuator>
  </transmission>
  <transmission name="Revolute 4_tran">
    <type>transmission_interface/SimpleTransmission</type>
    <joint name="Revolute 4">
      <hardwareInterface>hardware_interface/EffortJointInterface</hardwareInterface>
    </joint>
    <actuator name="Revolute 4_actr">
      <hardwareInterface>hardware_interface/EffortJointInterface</hardwareInterface>
      <mechanicalReduction>1</mechanicalReduction>
    </actuator>
  </transmission>
  <transmission name="Revolute 5_tran">
    <type>transmission_interface/SimpleTransmission</type>
    <joint name="Revolute 5">
      <hardwareInterface>hardware_interface/EffortJointInterface</hardwareInterface>
    </joint>
    <actuator name="Revolute 5_actr">
      <hardwareInterface>hardware_interface/EffortJointInterface</hardwareInterface>
      <mechanicalReduction>1</mechanicalReduction>
    </actuator>
  </transmission>
  <transmission name="Revolute 6_tran">
    <type>transmission_interface/SimpleTransmission</type>
    <joint name="Revolute 6">
      <hardwareInterface>hardware_interface/EffortJointInterface</hardwareInterface>
    </joint>
    <actuator name="Revolute 6_actr">
      <hardwareInterface>hardware_interface/EffortJointInterface</hardwareInterface>
      <mechanicalReduction>1</mechanicalReduction>
    </actuator>
  </transmission>
  <transmission name="Revolute 7_tran">
    <type>transmission_interface/SimpleTransmission</type>
    <joint name="Revolute 7">
      <hardwareInterface>hardware_interface/EffortJointInterface</hardwareInterface>
    </joint>
    <actuator name="Revolute 7_actr">
      <hardwareInterface>hardware_interface/EffortJointInterface</hardwareInterface>
      <mechanicalReduction>1</mechanicalReduction>
    </actuator>
  </transmission>
  <gazebo>
    <plugin name="control" filename="libgazebo_ros_control.so"/>
  </gazebo>
  <gazebo reference="base_link">
    <material>Gazebo/Silver</material>
    <mu1>0.2</mu1>
    <mu2>0.2</mu2>
    <selfCollide>true</selfCollide>
    <gravity>true</gravity>
  </gazebo>
  <gazebo reference="right_back_forward_wheel_1">
    <material>Gazebo/Silver</material>
    <mu1>0.2</mu1>
    <mu2>0.2</mu2>
    <selfCollide>true</selfCollide>
  </gazebo>
  <gazebo reference="left_back_forward_wheel_1">
    <material>Gazebo/Silver</material>
    <mu1>0.2</mu1>
    <mu2>0.2</mu2>
    <selfCollide>true</selfCollide>
  </gazebo>
  <gazebo reference="lidar_1">
    <material>Gazebo/Silver</material>
    <mu1>0.2</mu1>
    <mu2>0.2</mu2>
    <selfCollide>true</selfCollide>
  </gazebo>
  <gazebo reference="right_stand_1">
    <material>Gazebo/Silver</material>
    <mu1>0.2</mu1>
    <mu2>0.2</mu2>
    <selfCollide>true</selfCollide>
  </gazebo>
  <gazebo reference="right_front_forward_wheel_1">
    <material>Gazebo/Silver</material>
    <mu1>0.2</mu1>
    <mu2>0.2</mu2>
    <selfCollide>true</selfCollide>
  </gazebo>
  <gazebo reference="left_stand_1">
    <material>Gazebo/Silver</material>
    <mu1>0.2</mu1>
    <mu2>0.2</mu2>
    <selfCollide>true</selfCollide>
  </gazebo>
  <gazebo reference="left_front_forward_wheel_1">
    <material>Gazebo/Silver</material>
    <mu1>0.2</mu1>
    <mu2>0.2</mu2>
    <selfCollide>true</selfCollide>
  </gazebo>
  <link name="base_link">
    <inertial>
      <origin xyz="7.400190731617433e-16 0.045483770584439115 0.045364037650112765" rpy="0 0 0"/>
      <mass value="40.134720925774324"/>
      <inertia ixx="0.253793" iyy="0.18529" izz="0.383349" ixy="0.0" iyz="-0.000934" ixz="-0.0"/>
    </inertial>
    <visual>
      <origin xyz="0 0 0" rpy="0 0 0"/>
      <geometry>
        <mesh filename="package://1122_v3_description/meshes/base_link.stl" scale="0.001 0.001 0.001"/>
      </geometry>
      <material name="silver"/>
    </visual>
    <collision>
      <origin xyz="0 0 0" rpy="0 0 0"/>
      <geometry>
        <mesh filename="package://1122_v3_description/meshes/base_link.stl" scale="0.001 0.001 0.001"/>
      </geometry>
    </collision>
  </link>
  <link name="right_back_forward_wheel_1">
    <inertial>
      <origin xyz="-0.015000000000000013 2.7755575615628914e-17 -6.938893903907228e-18" rpy="0 0 0"/>
      <mass value="1.3679735342828132"/>
      <inertia ixx="0.001265" iyy="0.000735" izz="0.000735" ixy="-0.0" iyz="-0.0" ixz="-0.0"/>
    </inertial>
    <visual>
      <origin xyz="0.1185 -0.152 -0.025" rpy="0 0 0"/>
      <geometry>
        <mesh filename="package://1122_v3_description/meshes/right_back_forward_wheel_1.stl" scale="0.001 0.001 0.001"/>
      </geometry>
      <material name="silver"/>
    </visual>
    <collision>
      <origin xyz="0.1185 -0.152 -0.025" rpy="0 0 0"/>
      <geometry>
        <mesh filename="package://1122_v3_description/meshes/right_back_forward_wheel_1.stl" scale="0.001 0.001 0.001"/>
      </geometry>
    </collision>
  </link>
  <link name="left_back_forward_wheel_1">
    <inertial>
      <origin xyz="0.015000000000000013 2.7755575615628914e-17 -6.938893903907228e-18" rpy="0 0 0"/>
      <mass value="1.3679735342828132"/>
      <inertia ixx="0.001265" iyy="0.000735" izz="0.000735" ixy="0.0" iyz="-0.0" ixz="0.0"/>
    </inertial>
    <visual>
      <origin xyz="-0.1185 -0.152 -0.025" rpy="0 0 0"/>
      <geometry>
        <mesh filename="package://1122_v3_description/meshes/left_back_forward_wheel_1.stl" scale="0.001 0.001 0.001"/>
      </geometry>
      <material name="silver"/>
    </visual>
    <collision>
      <origin xyz="-0.1185 -0.152 -0.025" rpy="0 0 0"/>
      <geometry>
        <mesh filename="package://1122_v3_description/meshes/left_back_forward_wheel_1.stl" scale="0.001 0.001 0.001"/>
      </geometry>
    </collision>
  </link>
  <link name="lidar_1">
    <inertial>
      <origin xyz="0.0 -5.654319433712919e-18 0.009999999999999967" rpy="0 0 0"/>
      <mass value="0.789168074581756"/>
      <inertia ixx="0.000342" iyy="0.000342" izz="0.000631" ixy="0.0" iyz="-0.0" ixz="-0.0"/>
    </inertial>
    <visual>
      <origin xyz="-0.0 -0.0 -0.101" rpy="0 0 0"/>
      <geometry>
        <mesh filename="package://1122_v3_description/meshes/lidar_1.stl" scale="0.001 0.001 0.001"/>
      </geometry>
      <material name="silver"/>
    </visual>
    <collision>
      <origin xyz="-0.0 -0.0 -0.101" rpy="0 0 0"/>
      <geometry>
        <mesh filename="package://1122_v3_description/meshes/lidar_1.stl" scale="0.001 0.001 0.001"/>
      </geometry>
    </collision>
  </link>
  <link name="right_stand_1">
    <inertial>
      <origin xyz="-0.0025901819257813236 3.608224830031759e-14 0.024430928481979163" rpy="0 0 0"/>
      <mass value="0.10041834506100773"/>
      <inertia ixx="1.9e-05" iyy="2.4e-05" izz="8e-06" ixy="0.0" iyz="0.0" ixz="-0.0"/>
    </inertial>
    <visual>
      <origin xyz="0.0885 0.148 -0.002" rpy="0 0 0"/>
      <geometry>
        <mesh filename="package://1122_v3_description/meshes/right_stand_1.stl" scale="0.001 0.001 0.001"/>
      </geometry>
      <material name="silver"/>
    </visual>
    <collision>
      <origin xyz="0.0885 0.148 -0.002" rpy="0 0 0"/>
      <geometry>
        <mesh filename="package://1122_v3_description/meshes/right_stand_1.stl" scale="0.001 0.001 0.001"/>
      </geometry>
    </collision>
  </link>
  <link name="right_front_forward_wheel_1">
    <inertial>
      <origin xyz="-0.015000000000000013 0.0 3.469446951953614e-18" rpy="0 0 0"/>
      <mass value="1.3679735342828132"/>
      <inertia ixx="0.001265" iyy="0.000735" izz="0.000735" ixy="0.0" iyz="0.0" ixz="0.0"/>
    </inertial>
    <visual>
      <origin xyz="0.1185 0.148 -0.026" rpy="0 0 0"/>
      <geometry>
        <mesh filename="package://1122_v3_description/meshes/right_front_forward_wheel_1.stl" scale="0.001 0.001 0.001"/>
      </geometry>
      <material name="silver"/>
    </visual>
    <collision>
      <origin xyz="0.1185 0.148 -0.026" rpy="0 0 0"/>
      <geometry>
        <mesh filename="package://1122_v3_description/meshes/right_front_forward_wheel_1.stl" scale="0.001 0.001 0.001"/>
      </geometry>
    </collision>
  </link>
  <link name="left_stand_1">
    <inertial>
      <origin xyz="0.0025901819257813374 3.608224830031759e-14 0.024430928481979163" rpy="0 0 0"/>
      <mass value="0.10041834506100773"/>
      <inertia ixx="1.9e-05" iyy="2.4e-05" izz="8e-06" ixy="-0.0" iyz="0.0" ixz="0.0"/>
    </inertial>
    <visual>
      <origin xyz="-0.0885 0.148 -0.002" rpy="0 0 0"/>
      <geometry>
        <mesh filename="package://1122_v3_description/meshes/left_stand_1.stl" scale="0.001 0.001 0.001"/>
      </geometry>
      <material name="silver"/>
    </visual>
    <collision>
      <origin xyz="-0.0885 0.148 -0.002" rpy="0 0 0"/>
      <geometry>
        <mesh filename="package://1122_v3_description/meshes/left_stand_1.stl" scale="0.001 0.001 0.001"/>
      </geometry>
    </collision>
  </link>
  <link name="left_front_forward_wheel_1">
    <inertial>
      <origin xyz="0.015000000000000013 0.0 3.469446951953614e-18" rpy="0 0 0"/>
      <mass value="1.3679735342828132"/>
      <inertia ixx="0.001265" iyy="0.000735" izz="0.000735" ixy="0.0" iyz="0.0" ixz="0.0"/>
    </inertial>
    <visual>
      <origin xyz="-0.1185 0.148 -0.026" rpy="0 0 0"/>
      <geometry>
        <mesh filename="package://1122_v3_description/meshes/left_front_forward_wheel_1.stl" scale="0.001 0.001 0.001"/>
      </geometry>
      <material name="silver"/>
    </visual>
    <collision>
      <origin xyz="-0.1185 0.148 -0.026" rpy="0 0 0"/>
      <geometry>
        <mesh filename="package://1122_v3_description/meshes/left_front_forward_wheel_1.stl" scale="0.001 0.001 0.001"/>
      </geometry>
    </collision>
  </link>
  <joint name="Revolute 1" type="continuous">
    <origin xyz="-0.1185 0.152 0.025" rpy="0 0 0"/>
    <parent link="base_link"/>
    <child link="right_back_forward_wheel_1"/>
    <axis xyz="1.0 0.0 0.0"/>
  </joint>
  <joint name="Revolute 2" type="continuous">
    <origin xyz="0.1185 0.152 0.025" rpy="0 0 0"/>
    <parent link="base_link"/>
    <child link="left_back_forward_wheel_1"/>
    <axis xyz="1.0 0.0 0.0"/>
  </joint>
  <joint name="Revolute 3" type="continuous">
    <origin xyz="0.0 0.0 0.101" rpy="0 0 0"/>
    <parent link="base_link"/>
    <child link="lidar_1"/>
    <axis xyz="0.0 0.0 1.0"/>
  </joint>
  <joint name="Revolute 4" type="revolute">
    <origin xyz="-0.0885 -0.148 0.002" rpy="0 0 0"/>
    <parent link="base_link"/>
    <child link="right_stand_1"/>
    <axis xyz="0.0 0.0 1.0"/>
    <limit upper="0.436332" lower="-0.436332" effort="100" velocity="100"/>
  </joint>
  <joint name="Revolute 5" type="continuous">
    <origin xyz="-0.03 0.0 0.024" rpy="0 0 0"/>
    <parent link="right_stand_1"/>
    <child link="right_front_forward_wheel_1"/>
    <axis xyz="-1.0 0.0 0.0"/>
  </joint>
  <joint name="Revolute 6" type="revolute">
    <origin xyz="0.0885 -0.148 0.002" rpy="0 0 0"/>
    <parent link="base_link"/>
    <child link="left_stand_1"/>
    <axis xyz="0.0 0.0 1.0"/>
    <limit upper="0.436332" lower="-0.436332" effort="100" velocity="100"/>
  </joint>
  <joint name="Revolute 7" type="continuous">
    <origin xyz="0.03 0.0 0.024" rpy="0 0 0"/>
    <parent link="left_stand_1"/>
    <child link="left_front_forward_wheel_1"/>
    <axis xyz="1.0 0.0 0.0"/>
  </joint>
</robot>
