<?xml version="1.0" ?>
<!-- =================================================================================== -->
<!-- |    This document was autogenerated by xacro from urdf/car_1026_1.xacro          | -->
<!-- |    EDITING THIS FILE BY HAND IS NOT RECOMMENDED                                 | -->
<!-- =================================================================================== -->
<robot xmlns:xacro="http://www.ros.org/wiki/xacro" name="car_1026_1">
  <material name="silver">
    <color rgba="0.700 0.700 0.700 1.000"/>
  </material>
  <transmission name="Revolute 1_tran">
    <type>transmission_interface/SimpleTransmission</type>
    <joint name="Revolute 1">
      <hardwareInterface>hardware_interface/EffortJointInterface</hardwareInterface>
    </joint>
    <actuator name="Revolute 1_actr">
      <hardwareInterface>hardware_interface/EffortJointInterface</hardwareInterface>
      <mechanicalReduction>1</mechanicalReduction>
    </actuator>
  </transmission>
  <transmission name="Revolute 2_tran">
    <type>transmission_interface/SimpleTransmission</type>
    <joint name="Revolute 2">
      <hardwareInterface>hardware_interface/EffortJointInterface</hardwareInterface>
    </joint>
    <actuator name="Revolute 2_actr">
      <hardwareInterface>hardware_interface/EffortJointInterface</hardwareInterface>
      <mechanicalReduction>1</mechanicalReduction>
    </actuator>
  </transmission>
  <transmission name="Revolute 3_tran">
    <type>transmission_interface/SimpleTransmission</type>
    <joint name="Revolute 3">
      <hardwareInterface>hardware_interface/EffortJointInterface</hardwareInterface>
    </joint>
    <actuator name="Revolute 3_actr">
      <hardwareInterface>hardware_interface/EffortJointInterface</hardwareInterface>
      <mechanicalReduction>1</mechanicalReduction>
    </actuator>
  </transmission>
  <transmission name="Revolute 4_tran">
    <type>transmission_interface/SimpleTransmission</type>
    <joint name="Revolute 4">
      <hardwareInterface>hardware_interface/EffortJointInterface</hardwareInterface>
    </joint>
    <actuator name="Revolute 4_actr">
      <hardwareInterface>hardware_interface/EffortJointInterface</hardwareInterface>
      <mechanicalReduction>1</mechanicalReduction>
    </actuator>
  </transmission>
  <gazebo>
    <plugin name="control" filename="libgazebo_ros_control.so"/>
  </gazebo>
  <gazebo reference="base_link">
    <material>Gazebo/Silver</material>
    <mu1>0.2</mu1>
    <mu2>0.2</mu2>
    <selfCollide>true</selfCollide>
    <gravity>true</gravity>
  </gazebo>
  <gazebo reference="back_left_1">
    <material>Gazebo/Silver</material>
    <mu1>0.2</mu1>
    <mu2>0.2</mu2>
    <selfCollide>true</selfCollide>
  </gazebo>
  <gazebo reference="front_left_1">
    <material>Gazebo/Silver</material>
    <mu1>0.2</mu1>
    <mu2>0.2</mu2>
    <selfCollide>true</selfCollide>
  </gazebo>
  <gazebo reference="front_right_1">
    <material>Gazebo/Silver</material>
    <mu1>0.2</mu1>
    <mu2>0.2</mu2>
    <selfCollide>true</selfCollide>
  </gazebo>
  <gazebo reference="back_right_1">
    <material>Gazebo/Silver</material>
    <mu1>0.2</mu1>
    <mu2>0.2</mu2>
    <selfCollide>true</selfCollide>
  </gazebo>
  <gazebo reference="lidar_1">
    <material>Gazebo/Silver</material>
    <mu1>0.2</mu1>
    <mu2>0.2</mu2>
    <selfCollide>true</selfCollide>
  </gazebo>
  <link name="base_link">
    <inertial>
      <origin xyz="-0.054311834029112466 -0.03229517619233248 0.020804004659943264" rpy="0 0 0"/>
      <mass value="49.97215412857465"/>
      <inertia ixx="0.486898" iyy="0.245152" izz="0.619034" ixy="0.0" iyz="-0.016744" ixz="0.0"/>
    </inertial>
    <visual>
      <origin xyz="0 0 0" rpy="0 0 0"/>
      <geometry>
        <mesh filename="package://car_1026_1_description/meshes/base_link.stl" scale="0.001 0.001 0.001"/>
      </geometry>
      <material name="silver"/>
    </visual>
    <collision>
      <origin xyz="0 0 0" rpy="0 0 0"/>
      <geometry>
        <mesh filename="package://car_1026_1_description/meshes/base_link.stl" scale="0.001 0.001 0.001"/>
      </geometry>
    </collision>
  </link>
  <link name="back_left_1">
    <inertial>
      <origin xyz="-0.014999834029111966 2.3841356663889535e-07 4.971309441345693e-07" rpy="0 0 0"/>
      <mass value="1.3679735342828128"/>
      <inertia ixx="0.001265" iyy="0.000735" izz="0.000735" ixy="0.0" iyz="-0.0" ixz="-0.0"/>
    </inertial>
    <visual>
      <origin xyz="-0.064188 -0.103297 0.001027" rpy="0 0 0"/>
      <geometry>
        <mesh filename="package://car_1026_1_description/meshes/back_left_1.stl" scale="0.001 0.001 0.001"/>
      </geometry>
      <material name="silver"/>
    </visual>
    <collision>
      <origin xyz="-0.064188 -0.103297 0.001027" rpy="0 0 0"/>
      <geometry>
        <mesh filename="package://car_1026_1_description/meshes/back_left_1.stl" scale="0.001 0.001 0.001"/>
      </geometry>
    </collision>
  </link>
  <link name="front_left_1">
    <inertial>
      <origin xyz="-0.014999834029113153 2.3841356591725038e-07 4.97130944121342e-07" rpy="0 0 0"/>
      <mass value="1.3679735342828132"/>
      <inertia ixx="0.001265" iyy="0.000735" izz="0.000735" ixy="0.0" iyz="-0.0" ixz="-0.0"/>
    </inertial>
    <visual>
      <origin xyz="-0.064188 0.196703 0.001027" rpy="0 0 0"/>
      <geometry>
        <mesh filename="package://car_1026_1_description/meshes/front_left_1.stl" scale="0.001 0.001 0.001"/>
      </geometry>
      <material name="silver"/>
    </visual>
    <collision>
      <origin xyz="-0.064188 0.196703 0.001027" rpy="0 0 0"/>
      <geometry>
        <mesh filename="package://car_1026_1_description/meshes/front_left_1.stl" scale="0.001 0.001 0.001"/>
      </geometry>
    </collision>
  </link>
  <link name="front_right_1">
    <inertial>
      <origin xyz="-0.01499983402911273 2.3841356613929499e-07 4.971309432865063e-07" rpy="0 0 0"/>
      <mass value="1.3679735342828132"/>
      <inertia ixx="0.001265" iyy="0.000735" izz="0.000735" ixy="0.0" iyz="0.0" ixz="0.0"/>
    </inertial>
    <visual>
      <origin xyz="0.172812 0.196703 0.001027" rpy="0 0 0"/>
      <geometry>
        <mesh filename="package://car_1026_1_description/meshes/front_right_1.stl" scale="0.001 0.001 0.001"/>
      </geometry>
      <material name="silver"/>
    </visual>
    <collision>
      <origin xyz="0.172812 0.196703 0.001027" rpy="0 0 0"/>
      <geometry>
        <mesh filename="package://car_1026_1_description/meshes/front_right_1.stl" scale="0.001 0.001 0.001"/>
      </geometry>
    </collision>
  </link>
  <link name="back_right_1">
    <inertial>
      <origin xyz="-0.014999834029111647 2.3841356684706216e-07 4.971309433040704e-07" rpy="0 0 0"/>
      <mass value="1.3679735342828128"/>
      <inertia ixx="0.001265" iyy="0.000735" izz="0.000735" ixy="0.0" iyz="0.0" ixz="0.0"/>
    </inertial>
    <visual>
      <origin xyz="0.172812 -0.103297 0.001027" rpy="0 0 0"/>
      <geometry>
        <mesh filename="package://car_1026_1_description/meshes/back_right_1.stl" scale="0.001 0.001 0.001"/>
      </geometry>
      <material name="silver"/>
    </visual>
    <collision>
      <origin xyz="0.172812 -0.103297 0.001027" rpy="0 0 0"/>
      <geometry>
        <mesh filename="package://car_1026_1_description/meshes/back_right_1.stl" scale="0.001 0.001 0.001"/>
      </geometry>
    </collision>
  </link>
  <link name="lidar_1">
    <inertial>
      <origin xyz="1.6597088622893885e-07 2.3841356661113977e-07 0.010000497130944058" rpy="0 0 0"/>
      <mass value="0.6464869255592349"/>
      <inertia ixx="0.000235" iyy="0.000235" izz="0.000428" ixy="0.0" iyz="0.0" ixz="0.0"/>
    </inertial>
    <visual>
      <origin xyz="0.054312 0.048703 -0.152973" rpy="0 0 0"/>
      <geometry>
        <mesh filename="package://car_1026_1_description/meshes/lidar_1.stl" scale="0.001 0.001 0.001"/>
      </geometry>
      <material name="silver"/>
    </visual>
    <collision>
      <origin xyz="0.054312 0.048703 -0.152973" rpy="0 0 0"/>
      <geometry>
        <mesh filename="package://car_1026_1_description/meshes/lidar_1.stl" scale="0.001 0.001 0.001"/>
      </geometry>
    </collision>
  </link>
  <joint name="Revolute 1" type="continuous">
    <origin xyz="0.064188 0.103297 -0.001027" rpy="0 0 0"/>
    <parent link="base_link"/>
    <child link="back_left_1"/>
    <axis xyz="-1.0 0.0 -0.0"/>
  </joint>
  <joint name="Revolute 2" type="continuous">
    <origin xyz="0.064188 -0.196703 -0.001027" rpy="0 0 0"/>
    <parent link="base_link"/>
    <child link="front_left_1"/>
    <axis xyz="1.0 -0.0 0.0"/>
  </joint>
  <joint name="Revolute 3" type="continuous">
    <origin xyz="-0.172812 -0.196703 -0.001027" rpy="0 0 0"/>
    <parent link="base_link"/>
    <child link="front_right_1"/>
    <axis xyz="-1.0 0.0 -0.0"/>
  </joint>
  <joint name="Revolute 4" type="continuous">
    <origin xyz="-0.172812 0.103297 -0.001027" rpy="0 0 0"/>
    <parent link="base_link"/>
    <child link="back_right_1"/>
    <axis xyz="-1.0 0.0 -0.0"/>
  </joint>
  <joint name="Rigid 5" type="fixed">
    <origin xyz="-0.054312 -0.048703 0.152973" rpy="0 0 0"/>
    <parent link="base_link"/>
    <child link="lidar_1"/>
  </joint>
</robot>
