<?xml version="1.0" ?>
<!-- =================================================================================== -->
<!-- |    This document was autogenerated by xacro from urdf/1107car_copy.xacro        | -->
<!-- |    EDITING THIS FILE BY HAND IS NOT RECOMMENDED                                 | -->
<!-- =================================================================================== -->
<robot xmlns:xacro="http://www.ros.org/wiki/xacro" name="1107car_copy">
  <material name="silver">
    <color rgba="0.700 0.700 0.700 1.000"/>
  </material>
  <transmission name="Revolute 1_tran">
    <type>transmission_interface/SimpleTransmission</type>
    <joint name="Revolute 1">
      <hardwareInterface>hardware_interface/EffortJointInterface</hardwareInterface>
    </joint>
    <actuator name="Revolute 1_actr">
      <hardwareInterface>hardware_interface/EffortJointInterface</hardwareInterface>
      <mechanicalReduction>1</mechanicalReduction>
    </actuator>
  </transmission>
  <transmission name="Revolute 2_tran">
    <type>transmission_interface/SimpleTransmission</type>
    <joint name="Revolute 2">
      <hardwareInterface>hardware_interface/EffortJointInterface</hardwareInterface>
    </joint>
    <actuator name="Revolute 2_actr">
      <hardwareInterface>hardware_interface/EffortJointInterface</hardwareInterface>
      <mechanicalReduction>1</mechanicalReduction>
    </actuator>
  </transmission>
  <transmission name="Revolute 3_tran">
    <type>transmission_interface/SimpleTransmission</type>
    <joint name="Revolute 3">
      <hardwareInterface>hardware_interface/EffortJointInterface</hardwareInterface>
    </joint>
    <actuator name="Revolute 3_actr">
      <hardwareInterface>hardware_interface/EffortJointInterface</hardwareInterface>
      <mechanicalReduction>1</mechanicalReduction>
    </actuator>
  </transmission>
  <transmission name="Revolute 4_tran">
    <type>transmission_interface/SimpleTransmission</type>
    <joint name="Revolute 4">
      <hardwareInterface>hardware_interface/EffortJointInterface</hardwareInterface>
    </joint>
    <actuator name="Revolute 4_actr">
      <hardwareInterface>hardware_interface/EffortJointInterface</hardwareInterface>
      <mechanicalReduction>1</mechanicalReduction>
    </actuator>
  </transmission>
  <transmission name="Revolute 5_tran">
    <type>transmission_interface/SimpleTransmission</type>
    <joint name="Revolute 5">
      <hardwareInterface>hardware_interface/EffortJointInterface</hardwareInterface>
    </joint>
    <actuator name="Revolute 5_actr">
      <hardwareInterface>hardware_interface/EffortJointInterface</hardwareInterface>
      <mechanicalReduction>1</mechanicalReduction>
    </actuator>
  </transmission>
  <gazebo>
    <plugin name="control" filename="libgazebo_ros_control.so"/>
  </gazebo>
  <gazebo reference="base_link">
    <material>Gazebo/Silver</material>
    <mu1>0.2</mu1>
    <mu2>0.2</mu2>
    <selfCollide>true</selfCollide>
    <gravity>true</gravity>
  </gazebo>
  <gazebo reference="right_front_forward_wheel_1">
    <material>Gazebo/Silver</material>
    <mu1>0.2</mu1>
    <mu2>0.2</mu2>
    <selfCollide>true</selfCollide>
  </gazebo>
  <gazebo reference="left_front_forward_wheel_1">
    <material>Gazebo/Silver</material>
    <mu1>0.2</mu1>
    <mu2>0.2</mu2>
    <selfCollide>true</selfCollide>
  </gazebo>
  <gazebo reference="left_back_forward_wheel_1">
    <material>Gazebo/Silver</material>
    <mu1>0.2</mu1>
    <mu2>0.2</mu2>
    <selfCollide>true</selfCollide>
  </gazebo>
  <gazebo reference="right_back_forward_wheel_1">
    <material>Gazebo/Silver</material>
    <mu1>0.2</mu1>
    <mu2>0.2</mu2>
    <selfCollide>true</selfCollide>
  </gazebo>
  <gazebo reference="lidar_1">
    <material>Gazebo/Silver</material>
    <mu1>0.2</mu1>
    <mu2>0.2</mu2>
    <selfCollide>true</selfCollide>
  </gazebo>
  <link name="base_link">
    <inertial>
      <origin xyz="9.595015312934928e-17 0.018254911090556738 0.04207124303519063" rpy="0 0 0"/>
      <mass value="47.621616356853224"/>
      <inertia ixx="0.455353" iyy="0.219766" izz="0.611044" ixy="0.0" iyz="-0.023828" ixz="0.0"/>
    </inertial>
    <visual>
      <origin xyz="0 0 0" rpy="0 0 0"/>
      <geometry>
        <mesh filename="package://1107car_copy_description/meshes/base_link.stl" scale="0.001 0.001 0.001"/>
      </geometry>
      <material name="silver"/>
    </visual>
    <collision>
      <origin xyz="0 0 0" rpy="0 0 0"/>
      <geometry>
        <mesh filename="package://1107car_copy_description/meshes/base_link.stl" scale="0.001 0.001 0.001"/>
      </geometry>
    </collision>
  </link>
  <link name="right_front_forward_wheel_1">
    <inertial>
      <origin xyz="-0.015000000000000013 0.0 -6.938893903907228e-18" rpy="0 0 0"/>
      <mass value="1.3679735342828132"/>
      <inertia ixx="0.001265" iyy="0.000735" izz="0.000735" ixy="0.0" iyz="-0.0" ixz="0.0"/>
    </inertial>
    <visual>
      <origin xyz="0.1185 0.148 -0.025" rpy="0 0 0"/>
      <geometry>
        <mesh filename="package://1107car_copy_description/meshes/right_front_forward_wheel_1.stl" scale="0.001 0.001 0.001"/>
      </geometry>
      <material name="silver"/>
    </visual>
    <collision>
      <origin xyz="0.1185 0.148 -0.025" rpy="0 0 0"/>
      <geometry>
        <mesh filename="package://1107car_copy_description/meshes/right_front_forward_wheel_1.stl" scale="0.001 0.001 0.001"/>
      </geometry>
    </collision>
  </link>
  <link name="left_front_forward_wheel_1">
    <inertial>
      <origin xyz="0.015000000000000013 0.0 -6.938893903907228e-18" rpy="0 0 0"/>
      <mass value="1.3679735342828132"/>
      <inertia ixx="0.001265" iyy="0.000735" izz="0.000735" ixy="0.0" iyz="-0.0" ixz="0.0"/>
    </inertial>
    <visual>
      <origin xyz="-0.1185 0.148 -0.025" rpy="0 0 0"/>
      <geometry>
        <mesh filename="package://1107car_copy_description/meshes/left_front_forward_wheel_1.stl" scale="0.001 0.001 0.001"/>
      </geometry>
      <material name="silver"/>
    </visual>
    <collision>
      <origin xyz="-0.1185 0.148 -0.025" rpy="0 0 0"/>
      <geometry>
        <mesh filename="package://1107car_copy_description/meshes/left_front_forward_wheel_1.stl" scale="0.001 0.001 0.001"/>
      </geometry>
    </collision>
  </link>
  <link name="left_back_forward_wheel_1">
    <inertial>
      <origin xyz="0.015000000000000013 2.7755575615628914e-17 -6.938893903907228e-18" rpy="0 0 0"/>
      <mass value="1.3679735342828132"/>
      <inertia ixx="0.001265" iyy="0.000735" izz="0.000735" ixy="0.0" iyz="-0.0" ixz="0.0"/>
    </inertial>
    <visual>
      <origin xyz="-0.1185 -0.152 -0.025" rpy="0 0 0"/>
      <geometry>
        <mesh filename="package://1107car_copy_description/meshes/left_back_forward_wheel_1.stl" scale="0.001 0.001 0.001"/>
      </geometry>
      <material name="silver"/>
    </visual>
    <collision>
      <origin xyz="-0.1185 -0.152 -0.025" rpy="0 0 0"/>
      <geometry>
        <mesh filename="package://1107car_copy_description/meshes/left_back_forward_wheel_1.stl" scale="0.001 0.001 0.001"/>
      </geometry>
    </collision>
  </link>
  <link name="right_back_forward_wheel_1">
    <inertial>
      <origin xyz="-0.015000000000000013 2.7755575615628914e-17 -6.938893903907228e-18" rpy="0 0 0"/>
      <mass value="1.3679735342828132"/>
      <inertia ixx="0.001265" iyy="0.000735" izz="0.000735" ixy="-0.0" iyz="-0.0" ixz="-0.0"/>
    </inertial>
    <visual>
      <origin xyz="0.1185 -0.152 -0.025" rpy="0 0 0"/>
      <geometry>
        <mesh filename="package://1107car_copy_description/meshes/right_back_forward_wheel_1.stl" scale="0.001 0.001 0.001"/>
      </geometry>
      <material name="silver"/>
    </visual>
    <collision>
      <origin xyz="0.1185 -0.152 -0.025" rpy="0 0 0"/>
      <geometry>
        <mesh filename="package://1107car_copy_description/meshes/right_back_forward_wheel_1.stl" scale="0.001 0.001 0.001"/>
      </geometry>
    </collision>
  </link>
  <link name="lidar_1">
    <inertial>
      <origin xyz="-1.1042750148994577e-17 -2.42861286636753e-17 0.020734219801345738" rpy="0 0 0"/>
      <mass value="1.6163395242550898"/>
      <inertia ixx="0.000868" iyy="0.000868" izz="0.001262" ixy="-0.0" iyz="0.0" ixz="-0.0"/>
    </inertial>
    <visual>
      <origin xyz="-0.0 0.026 -0.136" rpy="0 0 0"/>
      <geometry>
        <mesh filename="package://1107car_copy_description/meshes/lidar_1.stl" scale="0.001 0.001 0.001"/>
      </geometry>
      <material name="silver"/>
    </visual>
    <collision>
      <origin xyz="-0.0 0.026 -0.136" rpy="0 0 0"/>
      <geometry>
        <mesh filename="package://1107car_copy_description/meshes/lidar_1.stl" scale="0.001 0.001 0.001"/>
      </geometry>
    </collision>
  </link>
  <joint name="Revolute 1" type="continuous">
    <origin xyz="-0.1185 -0.148 0.025" rpy="0 0 0"/>
    <parent link="base_link"/>
    <child link="right_front_forward_wheel_1"/>
    <axis xyz="-1.0 0.0 0.0"/>
  </joint>
  <joint name="Revolute 2" type="continuous">
    <origin xyz="0.1185 -0.148 0.025" rpy="0 0 0"/>
    <parent link="base_link"/>
    <child link="left_front_forward_wheel_1"/>
    <axis xyz="1.0 0.0 0.0"/>
  </joint>
  <joint name="Revolute 3" type="continuous">
    <origin xyz="0.1185 0.152 0.025" rpy="0 0 0"/>
    <parent link="base_link"/>
    <child link="left_back_forward_wheel_1"/>
    <axis xyz="1.0 0.0 0.0"/>
  </joint>
  <joint name="Revolute 4" type="continuous">
    <origin xyz="-0.1185 0.152 0.025" rpy="0 0 0"/>
    <parent link="base_link"/>
    <child link="right_back_forward_wheel_1"/>
    <axis xyz="-1.0 0.0 0.0"/>
  </joint>
  <joint name="Revolute 5" type="continuous">
    <origin xyz="0.0 -0.026 0.136" rpy="0 0 0"/>
    <parent link="base_link"/>
    <child link="lidar_1"/>
    <axis xyz="0.0 0.0 1.0"/>
  </joint>
</robot>
